[2022-12-16T12:50:54.486+0000] {taskinstance.py:1165} INFO - Dependencies all met for <TaskInstance: superforecast_v1.proceso manual__2022-12-16T12:48:16.442465+00:00 [queued]>
[2022-12-16T12:50:54.507+0000] {taskinstance.py:1165} INFO - Dependencies all met for <TaskInstance: superforecast_v1.proceso manual__2022-12-16T12:48:16.442465+00:00 [queued]>
[2022-12-16T12:50:54.508+0000] {taskinstance.py:1362} INFO - 
--------------------------------------------------------------------------------
[2022-12-16T12:50:54.508+0000] {taskinstance.py:1363} INFO - Starting attempt 2 of 2
[2022-12-16T12:50:54.508+0000] {taskinstance.py:1364} INFO - 
--------------------------------------------------------------------------------
[2022-12-16T12:50:54.544+0000] {taskinstance.py:1383} INFO - Executing <Task(PythonOperator): proceso> on 2022-12-16 12:48:16.442465+00:00
[2022-12-16T12:50:54.552+0000] {standard_task_runner.py:55} INFO - Started process 634 to run task
[2022-12-16T12:50:54.567+0000] {standard_task_runner.py:82} INFO - Running: ['***', 'tasks', 'run', 'superforecast_v1', 'proceso', 'manual__2022-12-16T12:48:16.442465+00:00', '--job-id', '74', '--raw', '--subdir', 'DAGS_FOLDER/predsuper_dag.py', '--cfg-path', '/tmp/tmpi1x6bo52']
[2022-12-16T12:50:54.581+0000] {standard_task_runner.py:83} INFO - Job 74: Subtask proceso
[2022-12-16T12:50:54.763+0000] {task_command.py:376} INFO - Running <TaskInstance: superforecast_v1.proceso manual__2022-12-16T12:48:16.442465+00:00 [running]> on host 26302dc28230
[2022-12-16T12:50:55.256+0000] {taskinstance.py:1592} INFO - Exporting the following env vars:
AIRFLOW_CTX_DAG_EMAIL=doloresferrando@gmail.com
AIRFLOW_CTX_DAG_OWNER=super
AIRFLOW_CTX_DAG_ID=superforecast_v1
AIRFLOW_CTX_TASK_ID=proceso
AIRFLOW_CTX_EXECUTION_DATE=2022-12-16T12:48:16.442465+00:00
AIRFLOW_CTX_TRY_NUMBER=2
AIRFLOW_CTX_DAG_RUN_ID=manual__2022-12-16T12:48:16.442465+00:00
[2022-12-16T12:51:03.032+0000] {taskinstance.py:1851} ERROR - Task failed with exception
Traceback (most recent call last):
  File "/usr/local/lib/python3.7/urllib/request.py", line 1350, in do_open
    encode_chunked=req.has_header('Transfer-encoding'))
  File "/usr/local/lib/python3.7/http/client.py", line 1281, in request
    self._send_request(method, url, body, headers, encode_chunked)
  File "/usr/local/lib/python3.7/http/client.py", line 1327, in _send_request
    self.endheaders(body, encode_chunked=encode_chunked)
  File "/usr/local/lib/python3.7/http/client.py", line 1276, in endheaders
    self._send_output(message_body, encode_chunked=encode_chunked)
  File "/usr/local/lib/python3.7/http/client.py", line 1036, in _send_output
    self.send(msg)
  File "/usr/local/lib/python3.7/http/client.py", line 976, in send
    self.connect()
  File "/usr/local/lib/python3.7/http/client.py", line 1443, in connect
    super().connect()
  File "/usr/local/lib/python3.7/http/client.py", line 948, in connect
    (self.host,self.port), self.timeout, self.source_address)
  File "/usr/local/lib/python3.7/socket.py", line 707, in create_connection
    for res in getaddrinfo(host, port, 0, SOCK_STREAM):
  File "/usr/local/lib/python3.7/socket.py", line 752, in getaddrinfo
    for res in _socket.getaddrinfo(host, port, family, type, proto, flags):
socket.gaierror: [Errno -5] No address associated with hostname

During handling of the above exception, another exception occurred:

Traceback (most recent call last):
  File "/home/airflow/.local/lib/python3.7/site-packages/airflow/operators/python.py", line 175, in execute
    return_value = self.execute_callable()
  File "/home/airflow/.local/lib/python3.7/site-packages/airflow/operators/python.py", line 193, in execute_callable
    return self.python_callable(*self.op_args, **self.op_kwargs)
  File "/opt/airflow/dags/super.py", line 17, in proceso
    format="csv", start_date=2017
  File "/home/airflow/.local/lib/python3.7/site-packages/pandas/util/_decorators.py", line 311, in wrapper
    return func(*args, **kwargs)
  File "/home/airflow/.local/lib/python3.7/site-packages/pandas/io/parsers/readers.py", line 586, in read_csv
    return _read(filepath_or_buffer, kwds)
  File "/home/airflow/.local/lib/python3.7/site-packages/pandas/io/parsers/readers.py", line 482, in _read
    parser = TextFileReader(filepath_or_buffer, **kwds)
  File "/home/airflow/.local/lib/python3.7/site-packages/pandas/io/parsers/readers.py", line 811, in __init__
    self._engine = self._make_engine(self.engine)
  File "/home/airflow/.local/lib/python3.7/site-packages/pandas/io/parsers/readers.py", line 1040, in _make_engine
    return mapping[engine](self.f, **self.options)  # type: ignore[call-arg]
  File "/home/airflow/.local/lib/python3.7/site-packages/pandas/io/parsers/c_parser_wrapper.py", line 51, in __init__
    self._open_handles(src, kwds)
  File "/home/airflow/.local/lib/python3.7/site-packages/pandas/io/parsers/base_parser.py", line 229, in _open_handles
    errors=kwds.get("encoding_errors", "strict"),
  File "/home/airflow/.local/lib/python3.7/site-packages/pandas/io/common.py", line 614, in get_handle
    storage_options=storage_options,
  File "/home/airflow/.local/lib/python3.7/site-packages/pandas/io/common.py", line 312, in _get_filepath_or_buffer
    with urlopen(req_info) as req:
  File "/home/airflow/.local/lib/python3.7/site-packages/pandas/io/common.py", line 212, in urlopen
    return urllib.request.urlopen(*args, **kwargs)
  File "/usr/local/lib/python3.7/urllib/request.py", line 222, in urlopen
    return opener.open(url, data, timeout)
  File "/usr/local/lib/python3.7/urllib/request.py", line 525, in open
    response = self._open(req, data)
  File "/usr/local/lib/python3.7/urllib/request.py", line 543, in _open
    '_open', req)
  File "/usr/local/lib/python3.7/urllib/request.py", line 503, in _call_chain
    result = func(*args)
  File "/usr/local/lib/python3.7/urllib/request.py", line 1393, in https_open
    context=self._context, check_hostname=self._check_hostname)
  File "/usr/local/lib/python3.7/urllib/request.py", line 1352, in do_open
    raise URLError(err)
urllib.error.URLError: <urlopen error [Errno -5] No address associated with hostname>
[2022-12-16T12:51:03.091+0000] {taskinstance.py:1406} INFO - Marking task as FAILED. dag_id=superforecast_v1, task_id=proceso, execution_date=20221216T124816, start_date=20221216T125054, end_date=20221216T125103
[2022-12-16T12:51:03.140+0000] {standard_task_runner.py:105} ERROR - Failed to execute job 74 for task proceso (<urlopen error [Errno -5] No address associated with hostname>; 634)
[2022-12-16T12:51:03.182+0000] {local_task_job.py:164} INFO - Task exited with return code 1
[2022-12-16T12:51:03.238+0000] {local_task_job.py:273} INFO - 0 downstream tasks scheduled from follow-on schedule check
