[2022-12-17T14:44:05.787+0000] {taskinstance.py:1165} INFO - Dependencies all met for <TaskInstance: superforecast_v1.proceso manual__2022-12-17T14:41:58.325826+00:00 [queued]>
[2022-12-17T14:44:05.799+0000] {taskinstance.py:1165} INFO - Dependencies all met for <TaskInstance: superforecast_v1.proceso manual__2022-12-17T14:41:58.325826+00:00 [queued]>
[2022-12-17T14:44:05.799+0000] {taskinstance.py:1362} INFO - 
--------------------------------------------------------------------------------
[2022-12-17T14:44:05.799+0000] {taskinstance.py:1363} INFO - Starting attempt 2 of 2
[2022-12-17T14:44:05.799+0000] {taskinstance.py:1364} INFO - 
--------------------------------------------------------------------------------
[2022-12-17T14:44:05.817+0000] {taskinstance.py:1383} INFO - Executing <Task(PythonOperator): proceso> on 2022-12-17 14:41:58.325826+00:00
[2022-12-17T14:44:05.822+0000] {standard_task_runner.py:55} INFO - Started process 26347 to run task
[2022-12-17T14:44:05.826+0000] {standard_task_runner.py:82} INFO - Running: ['***', 'tasks', 'run', 'superforecast_v1', 'proceso', 'manual__2022-12-17T14:41:58.325826+00:00', '--job-id', '99', '--raw', '--subdir', 'DAGS_FOLDER/predsuper_dag.py', '--cfg-path', '/tmp/tmpsy4yfx7h']
[2022-12-17T14:44:05.827+0000] {standard_task_runner.py:83} INFO - Job 99: Subtask proceso
[2022-12-17T14:44:05.893+0000] {task_command.py:376} INFO - Running <TaskInstance: superforecast_v1.proceso manual__2022-12-17T14:41:58.325826+00:00 [running]> on host 26302dc28230
[2022-12-17T14:44:06.140+0000] {taskinstance.py:1592} INFO - Exporting the following env vars:
AIRFLOW_CTX_DAG_EMAIL=doloresferrando@gmail.com
AIRFLOW_CTX_DAG_OWNER=super
AIRFLOW_CTX_DAG_ID=superforecast_v1
AIRFLOW_CTX_TASK_ID=proceso
AIRFLOW_CTX_EXECUTION_DATE=2022-12-17T14:41:58.325826+00:00
AIRFLOW_CTX_TRY_NUMBER=2
AIRFLOW_CTX_DAG_RUN_ID=manual__2022-12-17T14:41:58.325826+00:00
[2022-12-17T14:44:07.861+0000] {forecaster.py:927} INFO - Disabling daily seasonality. Run prophet with daily_seasonality=True to override this.
[2022-12-17T14:44:07.892+0000] {filesystem.py:123} DEBUG - input tempfile: /tmp/tmpvvi3dy_x/cdjg8jec.json
[2022-12-17T14:44:07.900+0000] {filesystem.py:123} DEBUG - input tempfile: /tmp/tmpvvi3dy_x/wacy59g5.json
[2022-12-17T14:44:07.902+0000] {model.py:1567} DEBUG - idx 0
[2022-12-17T14:44:07.903+0000] {model.py:1570} DEBUG - running CmdStan, num_threads: None
[2022-12-17T14:44:07.903+0000] {model.py:1580} DEBUG - CmdStan args: ['/home/***/.local/lib/python3.7/site-packages/prophet/stan_model/prophet_model.bin', 'random', 'seed=53733', 'data', 'file=/tmp/tmpvvi3dy_x/cdjg8jec.json', 'init=/tmp/tmpvvi3dy_x/wacy59g5.json', 'output', 'file=/tmp/tmpvvi3dy_x/prophet_modeln1qazobt/prophet_model-20221217144407.csv', 'method=optimize', 'algorithm=newton', 'iter=10000']
[2022-12-17T14:44:07.903+0000] {logging_mixin.py:120} WARNING - 14:44:07 - cmdstanpy - INFO - Chain [1] start processing
[2022-12-17T14:44:07.903+0000] {model.py:1583} INFO - Chain [1] start processing
[2022-12-17T14:44:08.657+0000] {logging_mixin.py:120} WARNING - 14:44:08 - cmdstanpy - INFO - Chain [1] done processing
[2022-12-17T14:44:08.657+0000] {model.py:1640} INFO - Chain [1] done processing
[2022-12-17T14:44:09.225+0000] {taskinstance.py:1851} ERROR - Task failed with exception
Traceback (most recent call last):
  File "/home/airflow/.local/lib/python3.7/site-packages/airflow/operators/python.py", line 175, in execute
    return_value = self.execute_callable()
  File "/home/airflow/.local/lib/python3.7/site-packages/airflow/operators/python.py", line 193, in execute_callable
    return self.python_callable(*self.op_args, **self.op_kwargs)
  File "/opt/airflow/dags/super.py", line 34, in proceso
    fcst[['ds', 'yhat']].merge(df,on='ds',how='left').to_csv('/dags/historico.csv')
  File "/home/airflow/.local/lib/python3.7/site-packages/pandas/core/generic.py", line 3482, in to_csv
    storage_options=storage_options,
  File "/home/airflow/.local/lib/python3.7/site-packages/pandas/io/formats/format.py", line 1105, in to_csv
    csv_formatter.save()
  File "/home/airflow/.local/lib/python3.7/site-packages/pandas/io/formats/csvs.py", line 243, in save
    storage_options=self.storage_options,
  File "/home/airflow/.local/lib/python3.7/site-packages/pandas/io/common.py", line 707, in get_handle
    newline="",
FileNotFoundError: [Errno 2] No such file or directory: '/dags/historico.csv'
[2022-12-17T14:44:09.236+0000] {taskinstance.py:1406} INFO - Marking task as FAILED. dag_id=superforecast_v1, task_id=proceso, execution_date=20221217T144158, start_date=20221217T144405, end_date=20221217T144409
[2022-12-17T14:44:09.253+0000] {standard_task_runner.py:105} ERROR - Failed to execute job 99 for task proceso ([Errno 2] No such file or directory: '/dags/historico.csv'; 26347)
[2022-12-17T14:44:09.294+0000] {local_task_job.py:164} INFO - Task exited with return code 1
[2022-12-17T14:44:09.364+0000] {local_task_job.py:273} INFO - 0 downstream tasks scheduled from follow-on schedule check
